{
 "cells": [
  {
   "cell_type": "code",
   "execution_count": 5,
   "metadata": {},
   "outputs": [],
   "source": [
    "import tensorflow as tf\n",
    "from tensorflow import keras"
   ]
  },
  {
   "cell_type": "code",
   "execution_count": 8,
   "metadata": {},
   "outputs": [],
   "source": [
    "#get data\n",
    "(train_images,train_labels),(test_images,test_tables)=keras.datasets.mnist.load_data()"
   ]
  },
  {
   "cell_type": "code",
   "execution_count": 11,
   "metadata": {},
   "outputs": [
    {
     "name": "stdout",
     "output_type": "stream",
     "text": [
      "WARNING:tensorflow:Output \"dense_5\" missing from loss dictionary. We assume this was done on purpose, and we will not be expecting any data to be passed to \"dense_5\" during training.\n"
     ]
    },
    {
     "ename": "ValueError",
     "evalue": "The model cannot be compiled because it has no loss to optimize.",
     "output_type": "error",
     "traceback": [
      "\u001b[0;31m---------------------------------------------------------------------------\u001b[0m",
      "\u001b[0;31mValueError\u001b[0m                                Traceback (most recent call last)",
      "\u001b[0;32m<ipython-input-11-8fecb604eada>\u001b[0m in \u001b[0;36m<module>\u001b[0;34m()\u001b[0m\n\u001b[1;32m      7\u001b[0m model.compile(optimizer=tf.train.AdamOptimizer(),\n\u001b[1;32m      8\u001b[0m              \u001b[0mLoss\u001b[0m\u001b[0;34m=\u001b[0m\u001b[0;34m'sparse_categorical_crossentropy'\u001b[0m\u001b[0;34m,\u001b[0m\u001b[0;34m\u001b[0m\u001b[0m\n\u001b[0;32m----> 9\u001b[0;31m              metrics=['accuracy'])\n\u001b[0m",
      "\u001b[0;32m/anaconda3/lib/python3.6/site-packages/tensorflow/python/training/checkpointable/base.py\u001b[0m in \u001b[0;36m_method_wrapper\u001b[0;34m(self, *args, **kwargs)\u001b[0m\n\u001b[1;32m    362\u001b[0m     \u001b[0mself\u001b[0m\u001b[0;34m.\u001b[0m\u001b[0m_setattr_tracking\u001b[0m \u001b[0;34m=\u001b[0m \u001b[0;32mFalse\u001b[0m  \u001b[0;31m# pylint: disable=protected-access\u001b[0m\u001b[0;34m\u001b[0m\u001b[0m\n\u001b[1;32m    363\u001b[0m     \u001b[0;32mtry\u001b[0m\u001b[0;34m:\u001b[0m\u001b[0;34m\u001b[0m\u001b[0m\n\u001b[0;32m--> 364\u001b[0;31m       \u001b[0mmethod\u001b[0m\u001b[0;34m(\u001b[0m\u001b[0mself\u001b[0m\u001b[0;34m,\u001b[0m \u001b[0;34m*\u001b[0m\u001b[0margs\u001b[0m\u001b[0;34m,\u001b[0m \u001b[0;34m**\u001b[0m\u001b[0mkwargs\u001b[0m\u001b[0;34m)\u001b[0m\u001b[0;34m\u001b[0m\u001b[0m\n\u001b[0m\u001b[1;32m    365\u001b[0m     \u001b[0;32mfinally\u001b[0m\u001b[0;34m:\u001b[0m\u001b[0;34m\u001b[0m\u001b[0m\n\u001b[1;32m    366\u001b[0m       \u001b[0mself\u001b[0m\u001b[0;34m.\u001b[0m\u001b[0m_setattr_tracking\u001b[0m \u001b[0;34m=\u001b[0m \u001b[0mprevious_value\u001b[0m  \u001b[0;31m# pylint: disable=protected-access\u001b[0m\u001b[0;34m\u001b[0m\u001b[0m\n",
      "\u001b[0;32m/anaconda3/lib/python3.6/site-packages/tensorflow/python/keras/engine/training.py\u001b[0m in \u001b[0;36mcompile\u001b[0;34m(self, optimizer, loss, metrics, loss_weights, sample_weight_mode, weighted_metrics, target_tensors, **kwargs)\u001b[0m\n\u001b[1;32m    460\u001b[0m       \u001b[0;32mif\u001b[0m \u001b[0mtotal_loss\u001b[0m \u001b[0;32mis\u001b[0m \u001b[0;32mNone\u001b[0m\u001b[0;34m:\u001b[0m\u001b[0;34m\u001b[0m\u001b[0m\n\u001b[1;32m    461\u001b[0m         \u001b[0;32mif\u001b[0m \u001b[0;32mnot\u001b[0m \u001b[0mself\u001b[0m\u001b[0;34m.\u001b[0m\u001b[0mlosses\u001b[0m\u001b[0;34m:\u001b[0m\u001b[0;34m\u001b[0m\u001b[0m\n\u001b[0;32m--> 462\u001b[0;31m           raise ValueError('The model cannot be compiled '\n\u001b[0m\u001b[1;32m    463\u001b[0m                            'because it has no loss to optimize.')\n\u001b[1;32m    464\u001b[0m         \u001b[0;32melse\u001b[0m\u001b[0;34m:\u001b[0m\u001b[0;34m\u001b[0m\u001b[0m\n",
      "\u001b[0;31mValueError\u001b[0m: The model cannot be compiled because it has no loss to optimize."
     ]
    }
   ],
   "source": [
    "#setup model\n",
    "model = keras.Sequential([\n",
    "    keras.layers.Flatten(input_shape=(28,28)),\n",
    "    keras.layers.Dense(128,activation=tf.nn.relu),\n",
    "    keras.layers.Dense(10,activation=tf.nn.softmax)\n",
    "])\n",
    "model.compile(optimizer=tf.train.AdamOptimizer(),\n",
    "             Loss='sparse_categorical_crossentropy',\n",
    "             metrics=['accuracy'])"
   ]
  },
  {
   "cell_type": "code",
   "execution_count": 10,
   "metadata": {},
   "outputs": [
    {
     "ename": "ValueError",
     "evalue": "('Error when checking model target: expected no data, but got:', array([5, 0, 4, ..., 5, 6, 8], dtype=uint8))",
     "output_type": "error",
     "traceback": [
      "\u001b[0;31m---------------------------------------------------------------------------\u001b[0m",
      "\u001b[0;31mValueError\u001b[0m                                Traceback (most recent call last)",
      "\u001b[0;32m<ipython-input-10-a5046c067117>\u001b[0m in \u001b[0;36m<module>\u001b[0;34m()\u001b[0m\n\u001b[1;32m      1\u001b[0m \u001b[0;31m#train model\u001b[0m\u001b[0;34m\u001b[0m\u001b[0;34m\u001b[0m\u001b[0m\n\u001b[0;32m----> 2\u001b[0;31m \u001b[0mmodel\u001b[0m\u001b[0;34m.\u001b[0m\u001b[0mfit\u001b[0m\u001b[0;34m(\u001b[0m\u001b[0mtrain_images\u001b[0m\u001b[0;34m,\u001b[0m\u001b[0mtrain_labels\u001b[0m\u001b[0;34m,\u001b[0m\u001b[0mepochs\u001b[0m\u001b[0;34m=\u001b[0m\u001b[0;36m5\u001b[0m\u001b[0;34m)\u001b[0m\u001b[0;34m\u001b[0m\u001b[0m\n\u001b[0m",
      "\u001b[0;32m/anaconda3/lib/python3.6/site-packages/tensorflow/python/keras/engine/training.py\u001b[0m in \u001b[0;36mfit\u001b[0;34m(self, x, y, batch_size, epochs, verbose, callbacks, validation_split, validation_data, shuffle, class_weight, sample_weight, initial_epoch, steps_per_epoch, validation_steps, **kwargs)\u001b[0m\n\u001b[1;32m   1276\u001b[0m         \u001b[0msteps_name\u001b[0m\u001b[0;34m=\u001b[0m\u001b[0;34m'steps_per_epoch'\u001b[0m\u001b[0;34m,\u001b[0m\u001b[0;34m\u001b[0m\u001b[0m\n\u001b[1;32m   1277\u001b[0m         \u001b[0msteps\u001b[0m\u001b[0;34m=\u001b[0m\u001b[0msteps_per_epoch\u001b[0m\u001b[0;34m,\u001b[0m\u001b[0;34m\u001b[0m\u001b[0m\n\u001b[0;32m-> 1278\u001b[0;31m         validation_split=validation_split)\n\u001b[0m\u001b[1;32m   1279\u001b[0m \u001b[0;34m\u001b[0m\u001b[0m\n\u001b[1;32m   1280\u001b[0m     \u001b[0;31m# Prepare validation data.\u001b[0m\u001b[0;34m\u001b[0m\u001b[0;34m\u001b[0m\u001b[0m\n",
      "\u001b[0;32m/anaconda3/lib/python3.6/site-packages/tensorflow/python/keras/engine/training.py\u001b[0m in \u001b[0;36m_standardize_user_data\u001b[0;34m(self, x, y, sample_weight, class_weight, batch_size, check_steps, steps_name, steps, validation_split)\u001b[0m\n\u001b[1;32m    915\u001b[0m           \u001b[0mfeed_output_shapes\u001b[0m\u001b[0;34m,\u001b[0m\u001b[0;34m\u001b[0m\u001b[0m\n\u001b[1;32m    916\u001b[0m           \u001b[0mcheck_batch_axis\u001b[0m\u001b[0;34m=\u001b[0m\u001b[0;32mFalse\u001b[0m\u001b[0;34m,\u001b[0m  \u001b[0;31m# Don't enforce the batch size.\u001b[0m\u001b[0;34m\u001b[0m\u001b[0m\n\u001b[0;32m--> 917\u001b[0;31m           exception_prefix='target')\n\u001b[0m\u001b[1;32m    918\u001b[0m \u001b[0;34m\u001b[0m\u001b[0m\n\u001b[1;32m    919\u001b[0m       \u001b[0;31m# Generate sample-wise weight values given the `sample_weight` and\u001b[0m\u001b[0;34m\u001b[0m\u001b[0;34m\u001b[0m\u001b[0m\n",
      "\u001b[0;32m/anaconda3/lib/python3.6/site-packages/tensorflow/python/keras/engine/training_utils.py\u001b[0m in \u001b[0;36mstandardize_input_data\u001b[0;34m(data, names, shapes, check_batch_axis, exception_prefix)\u001b[0m\n\u001b[1;32m    114\u001b[0m     \u001b[0;32mif\u001b[0m \u001b[0mdata\u001b[0m \u001b[0;32mis\u001b[0m \u001b[0;32mnot\u001b[0m \u001b[0;32mNone\u001b[0m \u001b[0;32mand\u001b[0m \u001b[0mhasattr\u001b[0m\u001b[0;34m(\u001b[0m\u001b[0mdata\u001b[0m\u001b[0;34m,\u001b[0m \u001b[0;34m'__len__'\u001b[0m\u001b[0;34m)\u001b[0m \u001b[0;32mand\u001b[0m \u001b[0mlen\u001b[0m\u001b[0;34m(\u001b[0m\u001b[0mdata\u001b[0m\u001b[0;34m)\u001b[0m\u001b[0;34m:\u001b[0m\u001b[0;34m\u001b[0m\u001b[0m\n\u001b[1;32m    115\u001b[0m       raise ValueError('Error when checking model ' + exception_prefix + ': '\n\u001b[0;32m--> 116\u001b[0;31m                        'expected no data, but got:', data)\n\u001b[0m\u001b[1;32m    117\u001b[0m     \u001b[0;32mreturn\u001b[0m \u001b[0;34m[\u001b[0m\u001b[0;34m]\u001b[0m\u001b[0;34m\u001b[0m\u001b[0m\n\u001b[1;32m    118\u001b[0m   \u001b[0;32mif\u001b[0m \u001b[0mdata\u001b[0m \u001b[0;32mis\u001b[0m \u001b[0;32mNone\u001b[0m\u001b[0;34m:\u001b[0m\u001b[0;34m\u001b[0m\u001b[0m\n",
      "\u001b[0;31mValueError\u001b[0m: ('Error when checking model target: expected no data, but got:', array([5, 0, 4, ..., 5, 6, 8], dtype=uint8))"
     ]
    }
   ],
   "source": [
    "#train model\n",
    "model.fit(train_images,train_labels,epochs=5)"
   ]
  },
  {
   "cell_type": "code",
   "execution_count": null,
   "metadata": {},
   "outputs": [],
   "source": [
    "#evaluate\n",
    "test_loss,test_acc = model.evaluate(test_images,test_lables)\n",
    "print('test accuracy:',test_acc)"
   ]
  },
  {
   "cell_type": "code",
   "execution_count": null,
   "metadata": {},
   "outputs": [],
   "source": [
    "#make predictions\n",
    "predictions = model.predict(test_images)"
   ]
  }
 ],
 "metadata": {
  "kernelspec": {
   "display_name": "Python 3",
   "language": "python",
   "name": "python3"
  },
  "language_info": {
   "codemirror_mode": {
    "name": "ipython",
    "version": 3
   },
   "file_extension": ".py",
   "mimetype": "text/x-python",
   "name": "python",
   "nbconvert_exporter": "python",
   "pygments_lexer": "ipython3",
   "version": "3.6.5"
  }
 },
 "nbformat": 4,
 "nbformat_minor": 2
}
